Workbook

Sheet Presupuesto
L1: Presupuesto Integrado Proyecto Automatización | T1: Presupuesto Integrado Proyecto Automatización por linea
B2: Tabla de tarifas laborales del proyecto | L2: Categoría | M2: Ítem / Paquete | N2: Cant. | O2: Unidad | P2: Valor unitario (COP) | Q2: Subtotal (COP) | R2: Comentarios / Referencias | T2: Línea | U2: Categoría | V2: Ítem / Paquete | W2: Cant. | X2: Unidad | Y2: Valor unitario (COP) | Z2: Subtotal (COP) | AA2: Comentarios / Referencias
B3: Tipo de recurso | C3: Rol en el proyecto | D3: Salario mensual referencia (COP) | E3: Horas mensuales | F3: Costo base por hora (COP) | G3: Factor de carga | H3: Costo final por hora (COP) | L3: 1. Equipos mecánicos y celda de paletizado | M3: Robot palletizer 4 ejes + controlador | N3: 1 | O3: und | P3: 352000000 | Q3: =N3*P3 -> 352000000 | R3: ABB IRB 460, 110 kg carga, 2,4 m alcance (standardbots.com) | T3: Monster Energy | U3: Control, seguridad y digitalización | V3: PLC Siemens S7-1200 CPU 1214C | W3: 1 | X3: und | Y3: 1900000 | Z3: 1900000 | AA3: Motion Control y control de variadores
B4: Estudiante Ingeniería Industrial | C4: Análisis de procesos | D4: 2000000 | E4: 176 | F4: =D4/E4 -> 11363.636 | G4: 1.5 | H4: =G4*F4 -> 17045.455 | M4: Herramental EOAT / gripper para packs o cajas | N4: 1 | O4: und | P4: 44500000 | Q4: =N4*P4 -> 44500000 | R4: Diseño específico para packs/cajas | U4: Control, seguridad y digitalización | V4: HMI Siemens KTP700 Basic | W4: 1 | X4: und | Y4: 3500000 | Z4: 3500000 | AA4: Panel operador con supervisión
B5: Estudiante Ingeniería Automatización | C5: Diseño de automatización | D5: 2200000 | E5: 176 | F5: =D5/E5 -> 12500 | G5: 1.5 | H5: =G5*F5 -> 18750 | M5: Pedestal, placa base y pernos | N5: 1 | O5: und | P5: 18500000 | Q5: =N5*P5 -> 18500000 | R5: Base mecánica del robot | U5: Control, seguridad y digitalización | V5: Barreras / escáner / enclavamientos | W5: 1 | X5: und | Y5: 18000000 | Z5: 18000000 | AA5: Seguridad funcional en línea
B6: Estudiante Programación PLC | C6: Desarrollo de control | D6: 2200000 | E6: 176 | F6: =D6/E6 -> 12500 | G6: 1.5 | H6: =G6*F6 -> 18750 | M6: Dispensador / magazine de pallets vacíos | N6: 1 | O6: und | P6: 27800000 | Q6: =N6*P6 -> 27800000 | R6: Pallet feeder estándar | U6: Control, seguridad y digitalización | V6: Sensores Machine Vision / Rayos X | W6: 5 | X6: und | Y6: 1000000 | Z6: 5000000 | AA6: Rechazo automático de latas defectuosas
B7: Estudiante Simulación Industrial | C7: Modelado y simulación | D7: 2100000 | E7: 176 | F7: =D7/E7 -> 11931.818 | G7: 1.5 | H7: =G7*F7 -> 17897.727 | M7: Conveyor modular de acumulación (12 m) | N7: 1 | O7: und | P7: 78000000 | Q7: =N7*P7 -> 78000000 | R7: Modular, velocidad compatible con línea | U7: Subtotal Control y seguridad | Z7: 28400000
B8: Estudiante Desarrollo SCADA | C8: Interfaz HMI y supervisión | D8: 2200000 | E8: 176 | F8: =D8/E8 -> 12500 | G8: 1.5 | H8: =G8*F8 -> 18750 | M8: Conveyor de rodillos salida pallet (5 m) | N8: 1 | O8: und | P8: 37500000 | Q8: =N8*P8 -> 37500000 | R8: Rodillos, integración con palletizado | U8: Software, pruebas y logística | V8: Consumibles FAT/SAT y calibración | W8: 1 | X8: und | Y8: 3000000 | Z8: 3000000 | AA8: Palets de prueba, film y packs
M9: Cerramiento y puertas de seguridad | N9: 1 | O9: und | P9: 22000000 | Q9: =N9*P9 -> 22000000 | R9: Seguridad funcional Pilz / escáner | U9: Subtotal Software, pruebas y logística | Z9: 3000000
B10: La tarifa laboral utilizada se estimó a partir de un promedio ponderado de salarios de auxiliares o practicantes de ingeniería en Colombia. Posteriormente, el valor mensual se convirtió a tarifa horaria considerando una jornada laboral estándar de 44 horas semanales (176 horas mensuales). Finalmente, el valor obtenido se multiplicó por un factor de carga de 1.5 para incluir el uso de infraestructura, herramientas y licencias de software requeridas para el desarrollo del proyecto de simulación. Este procedimiento sigue las prácticas de estimación de costos descritas en el A Guide to the Project Management Body of Knowledge (PMBOK® Guide) – Seventh Edition, en el proceso de estimación de costos del proyecto. | M10: Base civil, anclajes y nivelación | N10: 1 | O10: und | P10: 12000000 | Q10: =N10*P10 -> 12000000 | R10: Nivelación y montaje robusto | U10: Subtotal Línea | Z10: 31400000
L11: Subtotal Equipos mecánicos | Q11: =SUM(Q3:Q10) -> 592300000 | T11: Quatro (Triblock PET 1.5L) | U11: Equipos mecánicos | V11: Conveyor de preformas y llenadora | W11: 1 | X11: und | Y11: 15000000 | Z11: 15000000 | AA11: Automatización flujo de preformas
B12: Tabla de estimación de costos por paquete de trabajo (EDT) | L12: 2. Control, seguridad y digitalización | M12: PLC Siemens S7-1200 CPU 1214C | N12: 1 | O12: und | P12: 1900000 | Q12: =N12*P12 -> 1900000 | R12: 430 € aprox (Automation24) | U12: Subtotal Equipos mecánicos | Z12: 15000000
B13: EDT | C13: Actividad | E13: Recurso principal | F13: Horas estimadas | G13: Costo hora (COP) | H13: Costo total (COP) | M13: HMI Siemens KTP700 Basic | N13: 1 | O13: und | P13: 3500000 | Q13: =N13*P13 -> 3500000 | R13: 814.27 | U13: Control, seguridad y digitalización | V13: PLC Siemens S7-1200 CPU 1214C | W13: 1 | X13: und | Y13: 1900000 | Z13: 1900000 | AA13: Control de presión y temperatura
B14: 46023 | C14: Definición y análisis del proceso | E14: Estudiante Ing. Industrial | F14: 40 | G14: =$H$4 -> 17045.455 | H14: =F14*G14 -> 681818.18 | M14: ET200SP DI 8x24V | N14: 2 | O14: und | P14: 1000000 | Q14: =N14*P14 -> 2000000 | R14: USD 139,95 | U14: Control, seguridad y digitalización | V14: HMI Siemens KTP700 Basic | W14: 1 | X14: und | Y14: 3500000 | Z14: 3500000 | AA14: Visualización variables críticas
B15: 46054 | C15: Evaluación del sistema productivo | E15: Estudiante Ing. Industrial | F15: 35 | G15: =$H$4 -> 17045.455 | H15: =F15*G15 -> 596590.91 | M15: ET200SP DO 8x24V | N15: 2 | O15: und | P15: 1300000 | Q15: =N15*P15 -> 2600000 | R15: USD 175,43 | U15: Control, seguridad y digitalización | V15: Torquímetros Dinámicos / Feedback | W15: 4 | X15: und | Y15: 1200000 | Z15: 4800000 | AA15: Sellado hermético de tapas PET
B16: 46082 | C16: Diseño de solución de automatización | E16: Estudiante Ing. Automatización | F16: 45 | G16: =$H$5 -> 18750 | H16: =F16*G16 -> 843750 | M16: Safety relay Pilz PNOZ X4 | N16: 1 | O16: und | P16: 2100000 | Q16: =N16*P16 -> 2100000 | R16: USD 574,75 | U16: Subtotal Control y seguridad | Z16: 10200000
B17: 46113 | C17: Simulación del sistema productivo | E17: Estudiante Simulación | F17: 50 | G17: =$H$7 -> 17897.727 | H17: =F17*G17 -> 894886.36 | M17: Barreras / escáner / enclavamientos | N17: 1 | O17: und | P17: 18000000 | Q17: =N17*P17 -> 18000000 | R17: Seguridad funcional | U17: Software, pruebas y logística | V17: Instrumentación y calibración | W17: 1 | X17: und | Y17: 2500000 | Z17: 2500000 | AA17: Validación de variables críticas
B18: 46143 | C18: Diseño celda robotizada | E18: Estudiante Automatización | F18: 40 | G18: =$H$5 -> 18750 | H18: =F18*G18 -> 750000 | M18: Sensores fotoeléctricos / presencia | N18: 12 | O18: und | P18: 280000 | Q18: =N18*P18 -> 3360000 | R18: Sensor de presencia línea | U18: Subtotal Software, pruebas y logística | Z18: 2500000
B19: 46174 | C19: Desarrollo control PLC | E19: Estudiante PLC | F19: 50 | G19: =$H$5 -> 18750 | H19: =F19*G19 -> 937500 | M19: Switch industrial Ethernet | N19: 1 | O19: und | P19: 1500000 | Q19: =N19*P19 -> 1500000 | R19: Para red industrial | U19: Subtotal Línea | Z19: 27700000
B20: 46204 | C20: Desarrollo SCADA | E20: Estudiante SCADA | F20: 40 | G20: =$H$5 -> 18750 | H20: =F20*G20 -> 750000 | M20: Gateway / IPC OEE-MES lite | N20: 1 | O20: und | P20: 8000000 | Q20: =N20*P20 -> 8000000 | R20: Captura y digitalización datos | T20: Agua Brisa (Garrafón 20L) | U20: Equipos mecánicos y celda de paletizado | V20: Robot palletizer 4 ejes + controlador | W20: 1 | X20: und | Y20: 352000000 | Z20: 352000000 | AA20: Celda robótica para paletizado 20L
B21: 46235 | C21: Evaluación técnica y económica | E21: Estudiante Industrial | F21: 30 | G21: =$H$4 -> 17045.455 | H21: =F21*G21 -> 511363.64 | M21: Baliza, botonería, E-stops | N21: 1 | O21: und | P21: 3500000 | Q21: =N21*P21 -> 3500000 | R21: Seguridad y operación | U21: Equipos mecánicos y celda de paletizado | V21: Herramental EOAT / gripper | W21: 1 | X21: und | Y21: 44500000 | Z21: 44500000 | AA21: Adaptación a garrafones 20kg
B22: 46266 | C22: Documentación y entregables | E22: Estudiante Industrial | F22: 35 | G22: =$H$4 -> 17045.455 | H22: =F22*G22 -> 596590.91 | L22: Subtotal Control y seguridad | Q22: =SUM(Q12:Q21) -> 46460000 | U22: Equipos mecánicos y celda de paletizado | V22: Pedestal, base y pernos | W22: 1 | X22: und | Y22: 18500000 | Z22: 18500000 | AA22: Base mecánica del robot
H23: =SUM(H13:H22) -> 6562500 | L23: 3. Eléctrico, panel y neumática | M23: Tablero de control y montaje | N23: 1 | O23: und | P23: 18000000 | Q23: =N23*P23 -> 18000000 | R23: Panel local integración | U23: Equipos mecánicos y celda de paletizado | V23: Conveyor de salida pallet | W23: 1 | X23: und | Y23: 37500000 | Z23: 37500000 | AA23: Transporte a zona de almacenamiento
M24: Fuentes, breakers, contactores, borneras | N24: 1 | O24: und | P24: 9000000 | Q24: =N24*P24 -> 9000000 | R24: Potencia y control | U24: Subtotal Equipos mecánicos | Z24: 452500000
B25: Tabla de costos de infraestructura y software | M25: Cableado de potencia y control | N25: 1 | O25: und | P25: 15000000 | Q25: =N25*P25 -> 15000000 | R25: Incluye red y bandejas | U25: Control, seguridad y digitalización | V25: Gateway / IPC OEE-MES lite | W25: 1 | X25: und | Y25: 8000000 | Z25: 8000000 | AA25: Captura de producción y control
B26: Software / Herramienta | C26: Uso en el proyecto | E26: Tipo | F26: Cantidad | G26: Valor unitario (COP) | H26: Costo total (COP) | M26: Bandejas / canaletas / prensaestopas | N26: 1 | O26: und | P26: 6500000 | Q26: =N26*P26 -> 6500000 | R26: Organización de cableado | U26: Subtotal Control y seguridad | Z26: 8000000
B27: Software y herramientas de desarrollo | M27: Sistema neumático / vacío gripper | N27: 1 | O27: und | P27: 10000000 | Q27: =N27*P27 -> 10000000 | R27: Compresor / válvulas / tubería | U27: Eléctrico, panel y neumática | V27: Tablero, breakers, cableado, bandejas, neumática y variadores | W27: 1 | X27: und | Y27: 59600000 | Z27: 59600000 | AA27: Aplica a robot y conveyors
B28: Factory I/O | C28: Simulación de procesos industriales y pruebas de PLC | E28: Académica | F28: 1 | G28: 400000 | H28: =G28*F28 -> 400000 | M28: Variadores / accionamientos auxiliares | N28: 2 | O28: und | P28: 550000 | Q28: =N28*P28 -> 1100000 | R28: Motorización auxiliar | U28: Subtotal eléctrico y neumática | Z28: 59600000
B29: Studio 5000 | C29: Programación PLC y lógica Ladder | E29: Académica | F29: 1 | G29: 0 | H29: =G29*F29 -> 0 | L29: Subtotal eléctrico y neumático | Q29: =SUM(Q23:Q28) -> 59600000 | S29: - | U29: Software, pruebas y logística | V29: Consumibles FAT/SAT y calibración | W29: 1 | X29: und | Y29: 3000000 | Z29: 3000000 | AA29: Palets de prueba, film y packs
B30: NX (Siemens NX) | C30: Diseño CAD y modelado de componentes | E30: Académica | F30: 1 | G30: 0 | H30: =G30*F30 -> 0 | L30: 4. Software, pruebas y logística | M30: TIA Portal STEP 7 Basic V20 | N30: 1 | O30: und | P30: 1900000 | Q30: =N30*P30 -> 1900000 | R30: Licencia básica PLC | U30: Software, pruebas y logística | V30: Licencias completas robot + PLC + SCADA | W30: 1 | X30: und | Y30: 12200000 | Z30: 12200000 | AA30: TIA Portal, WinCC, RobotStudio, Palletizing PowerPac
B31: Autodesk Inventor | C31: Modelado 3D de sistemas mecánicos | E31: Académica | F31: 1 | G31: 0 | H31: =G31*F31 -> 0 | M31: WinCC Basic engineering | N31: 1 | O31: und | P31: 1100000 | Q31: =N31*P31 -> 1100000 | R31: Licencia SCADA | U31: Software, pruebas y logística | V31: Instrumentación / alquiler medición | W31: 1 | X31: und | Y31: 2500000 | Z31: 2500000 | AA31: Medición y seguridad tests
B32: ABB RobotStudio | C32: Simulación de robots industriales | E32: Académica | F32: 1 | G32: 0 | H32: =G32*F32 -> 0 | M32: ABB RobotStudio Premium 1 año | N32: 1 | O32: und | P32: 4600000 | Q32: =N32*P32 -> 4600000 | R32: Software simulación robot | U32: Software, pruebas y logística | V32: Flete, nacionalización y maniobras | W32: 1 | X32: und | Y32: 35000000 | Z32: 35000000 | AA32: Transporte y logística
B33: Tecnomatix Plant Simulation | C33: Simulación de sistemas productivos | E33: Académica | F33: 1 | G33: 0 | H33: =G33*F33 -> 0 | M33: ABB Palletizing PowerPac 1 año | N33: 1 | O33: und | P33: 4600000 | Q33: =N33*P33 -> 4600000 | R33: Librería palletizado | U33: Subtotal Software, pruebas y logística | Z33: 52700000
B34: GitHub | C34: Repositorio del proyecto | E34: Gratuita | F34: 1 | G34: 0 | H34: =G34*F34 -> 0 | M34: Consumibles FAT/SAT | N34: 1 | O34: und | P34: 3000000 | Q34: =N34*P34 -> 3000000 | R34: Pallets, film, packs de prueba | U34: Subtotal Línea | Z34: 572800000
B35: Infraestructura y servicios | M35: Instrumentación / alquiler medición | N35: 1 | O35: und | P35: 2500000 | Q35: =N35*P35 -> 2500000 | R35: Medición y seguridad tests | T35: TOTAL GENERAL | Z35: 746898675 | AA35: COP
B36: Energía eléctrica | C36: Desarrollo del proyecto | F36: 4 | G36: 100000 | H36: =G36*F36 -> 400000 | M36: Flete, nacionalización y maniobras | N36: 1 | O36: und | P36: 35000000 | Q36: =N36*P36 -> 35000000 | R36: Transporte y logística
B37: Servicio de internet | C37: Desarrollo del proyecto | F37: 4 | G37: 100000 | H37: =G37*F37 -> 400000 | L37: Subtotal software, pruebas y logística | Q37: =SUM(Q30:Q36) -> 52700000
L38: 5. Mano de obra directa (EDT) | M38: Estudiante Ing. Industrial | N38: 140 | O38: h | P38: 17045 | Q38: =N38*P38 -> 2386300 | R38: EDT 1.1,1.2,1.8,1.9 | T38: Total linea 1 | U38: =Z10 -> 31400000
M39: Estudiante Ing. Automatización | N39: 85 | O39: h | P39: 18750 | Q39: =N39*P39 -> 1593750 | R39: EDT 1.3,1.5 | T39: Total costos directos | U39: =U38+Q43+Q48 -> 44262450
M40: Estudiante PLC | N40: 50 | O40: h | P40: 18750 | Q40: =N40*P40 -> 937500 | R40: EDT 1.6 | T40: Costos indirectos de proyecto- 6% | U40: =$U$39*0.06 -> 2655747
...

Sheet APU
A1: Demanda Estimada | F1: Indicador Consumo agua | I1: Coversiones
A2: Producto | B2: Unidades/año | C2: Contenido (L) /Unidad | D2: Contenido Azucar (g) /Unidad | F2: Semanal | G2: 1,38-1,41 | I2: 1000 | J2: 1
A3: Monster | B3: 21850000 | C3: =473/1000 -> 0.473 | D3: =B27*C3/0.1 -> 56.76 | F3: Mensual | G3: 1.32 | I3: Litros | J3: m3
A4: Brisa Garrafon 5Gl | B4: 4227600 | C4: 18.9271 | D4: 0 | F4: Informe KOF 2024 | G4: 1.36
A5: Quatro 1.5L | B5: 35720000 | C5: 1.5 | D5: =B43*C5/0.1 -> 73.5 | I5: Materias Primas
F6: Precios Insumos Industriales | I6: Productos | J6: Monster | K6: Brisa | L6: Quatro | M6: Total
F7: Agua fijo (COP/mes) | G7: 12734.31 | I7: Agua | J7: =12*G7+((B3*C3*(G4-0.36))/1000)*G8 -> 52416229 | K7: =12*G7+((B4*C4*(G4-0.36))/1000)*G8 -> 4.0478757e+08 | L7: =12*G7+((B5*C5*(G4-0.36))/1000)*G8 -> 2.7110205e+08 | M7: =J7+K7+L7 -> 7.2830585e+08
A8: Valores Actuales Estandar | F8: Agua consumo (COP/m3) | G8: 5056.91 | I8: Azucar | J8: =(B3*D3/1000)*G9 -> 4365525120 | K8: 0 | L8: =(B5*D5/1000)*G9 -> 9241478400 | M8: =J8+K8+L8 -> 13607003520
A9: Producto | B9: Precio Sugerido | C9: Precio Directo | D9: Costo Produccion | F9: Azucar refinada DANE (COP/Kg) | G9: 3520 | I9: Envase
A10: Monster 473 ml | B10: 8500 | C10: 7000 | D10: =C10*0.54 -> 3780 | I10: Otros
A11: Brisa Garrafon 5Gl | B11: 15000 | C11: 12600 | D11: =C11*0.54 -> 6804 | I11: Mano de obra
A12: Quatro 1.5L | B12: 4500 | C12: 3750 | D12: =C12*0.54 -> 2025 | I12: Directa
I13: Indirecta
I14: Servicios
A15: Informe KOF 2024 | I15: Agua | J15: =12*G7+((B3*C3*(G4-1))/1000)*G8 -> 18967642 | K15: =12*G7+((B4*C4*(G4-1))/1000)*G8 -> 1.4582133e+08 | L15: =12*G7+((B5*C5*(G4-1))/1000)*G8 -> 97694537 | M15: =SUM(J15:L15) -> 2.6248351e+08
A16: Margen Bruto | B16: 0.46 | I16: Luz
A17: Margen Neto | B17: 0.088 | I17: Gas
I18: Total | J18: =D10*B3 -> 82593000000 | K18: =B4*D11 -> 28764590400 | L18: =B5*D12 -> 72333000000 | M18: =J18+K18+L18 -> 183690590400
A20: Informacion Nutriconal Monster 473 ml
A21: Tamaño de procion | B21: 1 | C21: vaso (200 ml)
A22: Porciones por Envase aprox. | B22: 2
A23: Calorias (kcal) | B23: Por 100 ml | C23: Por porcion
B24: 47 | C24: 94
A25: Carbohidratos totales (g) | B25: 12 | C25: 24
A26: Azucares totales (g) | B26: 12 | C26: 24
A27: Azucares añadidos (g) | B27: 12 | C27: 24
A28: Riboflavina (mg) | B28: 0.72 | C28: 1.4
A29: Niacina (mg) | B29: 8.5 | C29: 17
A30: Vitamina B6 (mg) | B30: 0.85 | C30: 1.7
A31: Vitamina B12 (ug) | B31: 2.5 | C31: 5
A34: Informacion Nutriconal Quatro 1,5L
A35: Tamaño de procion | B35: 1 | C35: vaso (200 ml)
A36: Porciones por Envase aprox. | B36: 2
A37: Calorias (kcal) | B37: Por 100 ml | C37: Por porcion
B38: 20 | C38: 40
A39: Grasa Total (g) | B39: 0 | C39: 0
A40: Grasa trans (mg) | B40: 0 | C40: 0
A41: Carbohidratos totales (g) | B41: 4.9 | C41: 9.8
A42: Azucares totales (g) | B42: 4.9 | C42: 9.8
A43: Azucares añadidos (g) | B43: 4.9 | C43: 9.8
...

Sheet Flujo de caja
C5: Linea Monster 473 ml | E5: Linea Quatro 1.5L | G5: Linea Brissa 5Gl
B6: Año | C6: Ingresos | D6: Costo fabriacacion | E6: Ingresos | F6: Costo fabriacacion | G6: Ingresos | H6: Costo fabriacacion | I6: Utilidad Bruta | J6: Inversiones | K6: Costos Operativos | L6: Costos mantenimiento | M6: EBITDA | N6: Flujo Neto
B7: 0 | C7: 0 | D7: 0 | E7: 0 | F7: 0 | G7: 0 | H7: 0 | I7: =(C7-D7)+(E7+F7)+(G7-H7) -> 0 | J7: =Presupuesto!Q53 -> 1016016859 | K7: 0 | L7: 0 | M7: =I7-J7-K7-L7 -> -1016016859 | N7: =M7 -> -1016016859
B8: 1 | C8: =APU!B3*APU!C10 -> 152950000000 | D8: =APU!J18 -> 82593000000 | E8: =APU!B4*APU!C11 -> 53267760000 | F8: =APU!K18 -> 28764590400 | G8: =APU!B5*APU!C12 -> 133950000000 | H8: =APU!L18 -> 72333000000 | I8: =(C8-D8)+(E8+F8)+(G8-H8) -> 214006350400 | J8: 0 | K8: 0 | L8: 0 | M8: =I8-J8-K8-L8 -> 214006350400 | N8: =N7+M8 -> 212990333542
A14: Bibliografia : | B14: Monster Green 473ml 4 Pack. (2026). https://www.entuhogar.coca-cola.com.co/monster-green-473ml-4-pack Gaseosa Quatro Original 1.5 L 2 Unidades (2026). https://www.entuhogar.coca-cola.com.co/gaseosa-quatro-original-1-5-l-2-unidades Agua Brisa Sin Gas Botellón 5 GL 1 Unidad https://www.entuhogar.coca-cola.com.co/agua-brisa-sin-gas-botellon-5-gl-1-unidad Informe Integrado KOF II 2024. (2025). https://investors.coca-colafemsa.com/assets/files/reportes_resultados_esp/2024/informe-integrado-kof-ii-2024-esp.pdf
